Workbook
Name Antal_instanser: 'DKK - Safespring-tjenester 2025'!#REF!
Name Antal_instanser: 'EUR - Safespring services 2025'!#REF!
Name Antal_instanser: 'NOK - Safespring tjenester 2025'!#REF!
Name Antal_instanser: 'SEK - Safesprings tjänster 2025'!#REF!
Name BAAS_large_EUR: Data!$F$27
Name BAAS_large_SEK: Data!$E$27
Name BAAS_large.fee_EUR: Data!$F$25
Name BAAS_large.fee_SEK: Data!$E$25
Name BAAS_on.demand_EUR: Data!$F$23
Name BAAS_on.demand_SEK: Data!$E$23
Name BAAS_small_EUR: Data!$F$26
Name BAAS_small_SEK: Data!$E$26
Name BAAS_small.fee_EUR: Data!$F$24
Name BAAS_small.fee_SEK: Data!$E$24
Name Disk__GB: 'DKK - Safespring-tjenester 2025'!#REF!
Name Disk__GB: 'EUR - Safespring services 2025'!#REF!
Name Disk__GB: 'NOK - Safespring tjenester 2025'!#REF!
Name Disk__GB: 'SEK - Safesprings tjänster 2025'!#REF!
Name EUR: Data!$K$4
Name IAAS_GPU_A2_EUR: Data!$F$9
Name IAAS_GPU_A2_SEK: Data!$E$9
Name IAAS_gpu_EUR: Data!$F$7
Name IAAS_GPU_H100_EUR: Data!$F$10
Name IAAS_GPU_H100_SEK: Data!$E$10
Name IAAS_gpu_SEK: Data!$E$7
Name IAAS_gpu_SUNET: Data!$G$7
Name IAAS_nvme_EUR: Data!$F$6
Name IAAS_nvme_SEK: Data!$E$6
Name IAAS_nvme_SUNET: Data!$G$6
Name IAAS_pcpu_EUR: Data!$F$8
Name IAAS_pcpu_SEK: Data!$E$8
Name IAAS_pcpu_SUNET: Data!$G$8
Name IAAS_ram_EUR: Data!$F$3
Name IAAS_ram_SEK: Data!$E$3
Name IAAS_ram_SUNET: Data!$G$3
Name IAAS_ram_sunet_b_m: Data!$G$9
Name IAAS_ssd_EUR: Data!$F$4
Name IAAS_ssd_SEK: Data!$E$4
Name IAAS_ssd_SUNET: Data!$G$11
Name IAAS_vcpu_EUR: Data!$F$5
Name IAAS_vcpu_SEK: Data!$E$5
Name IAAS_vcpu_SUNET: Data!$G$5
Name IAAS_vcpu_sunet_b_m: Data!$G$10
Name INSTANCE_p1.2xlarge.16d_EUR: Data!$F$14
Name INSTANCE_p1.2xlarge.16d_SEK: Data!$E$14
Name INSTANCE_p1.4xlarge.16d_EUR: Data!$F$15
Name INSTANCE_p1.4xlarge.16d_SEK: Data!$E$15
Name INSTANCE_p1.8xlarge.32d_EUR: Data!$F$16
Name INSTANCE_p1.8xlarge.32d_SEK: Data!$E$16
Name list_Antal_instanser: 'DKK - Safespring-tjenester 2025'!#REF!
Name list_Antal_instanser: 'EUR - Safespring services 2025'!#REF!
Name list_Antal_instanser: 'NOK - Safespring tjenester 2025'!#REF!
Name list_Antal_instanser: 'SEK - Safesprings tjänster 2025'!#REF!
Name list_Disk__GB: 'DKK - Safespring-tjenester 2025'!#REF!
Name list_Disk__GB: 'EUR - Safespring services 2025'!#REF!
Name list_Disk__GB: 'NOK - Safespring tjenester 2025'!#REF!
Name list_Disk__GB: 'SEK - Safesprings tjänster 2025'!#REF!
Name list_RAM__GB: 'DKK - Safespring-tjenester 2025'!#REF!
Name list_RAM__GB: 'EUR - Safespring services 2025'!#REF!
Name list_RAM__GB: 'NOK - Safespring tjenester 2025'!#REF!

Sheet EUR - Safespring services 2025
B5: Price calculator 2026-05-25
B8: Contact Safespring | D8: Currency
B9: Call us: +46 8-55 10 73 56
B10: hello@safespring.com
B15: Safespring Kubernetes Engine
B18: All prices are in EUR, excluding VAT.
B19: Instructions: Fill in the desired quantity in the colored fields.
B22: Control plane
B23: The first control plane is managed, but unmanaged control planes can be added afterwards.
B24: Product ID | G24: Hourly | H24: 30 days | I24: Amount | K24: Infrastructure
B25: Managed Control plane | G25: =H25/720 -> 0.63972222 | H25: 460.6 | K25: =ROUNDUP(I25*H25,2) -> 0
B26: Unmanaged Control plane | G26: =H26/720 -> 0 | H26: 0 | K26: =ROUNDUP(I26*H26,2) -> 0
B27: Total | I27: =SUM(I14:I26) -> 0 | K27: =SUM(K14:K26) -> 0
B30: Safespring Compute | IaaS
B33: Infrastructure as a service can run on an open source license or with a Windows license.
B34: All prices are in EUR, excluding VAT.
B35: Instructions: Fill in the desired quantity in the colored fields.
B38: Flavors with local NVMe storage
B39: Central block storage can be purchased for the instances. See "Central block storage" in the price list.
B40: Product ID | C40: vCPU | D40: RAM (GB) | E40: Local disk (GB) | F40: Hourly | G40: 30 days | I40: Amount | K40: Infrastructure
B41: FLAVOR-l2. c2 r4. 100 | C41: 2 | D41: 4 | E41: 100 | F41: =G41/720 -> 0.062666667 | G41: =C41*IAAS_vcpu_EUR+D41*IAAS_ram_EUR+E41*IAAS_nvme_EUR -> 45.12 | K41: =ROUNDUP(I41*G41,2) -> 0
B42: FLAVOR-l2. c2 r4. 500 | C42: 2 | D42: 4 | E42: 500 | F42: =G42/720 -> 0.11488889 | G42: =C42*IAAS_vcpu_EUR+D42*IAAS_ram_EUR+E42*IAAS_nvme_EUR -> 82.72 | K42: =ROUNDUP(I42*G42,2) -> 0
B43: FLAVOR-l2. c2 r4. 1000 | C43: 2 | D43: 4 | E43: 1000 | F43: =G43/720 -> 0.18016667 | G43: =C43*IAAS_vcpu_EUR+D43*IAAS_ram_EUR+E43*IAAS_nvme_EUR -> 129.72 | K43: =ROUNDUP(I43*G43,2) -> 0
B44: FLAVOR-l2. c4 r8. 100 | C44: 4 | D44: 8 | E44: 100 | F44: =G44/720 -> 0.11227778 | G44: =C44*IAAS_vcpu_EUR+D44*IAAS_ram_EUR+E44*IAAS_nvme_EUR -> 80.84 | K44: =ROUNDUP(I44*G44,2) -> 0
B45: FLAVOR-l2. c4 r8. 500 | C45: 4 | D45: 8 | E45: 500 | F45: =G45/720 -> 0.1645 | G45: =C45*IAAS_vcpu_EUR+D45*IAAS_ram_EUR+E45*IAAS_nvme_EUR -> 118.44 | K45: =ROUNDUP(I45*G45,2) -> 0
B46: FLAVOR-l2. c4 r8. 1000 | C46: 4 | D46: 8 | E46: 1000 | F46: =G46/720 -> 0.22977778 | G46: =C46*IAAS_vcpu_EUR+D46*IAAS_ram_EUR+E46*IAAS_nvme_EUR -> 165.44 | K46: =ROUNDUP(I46*G46,2) -> 0
B47: FLAVOR-l2. c8 r16. 100 | C47: 8 | D47: 16 | E47: 100 | F47: =G47/720 -> 0.2115 | G47: =C47*IAAS_vcpu_EUR+D47*IAAS_ram_EUR+E47*IAAS_nvme_EUR -> 152.28 | K47: =ROUNDUP(I47*G47,2) -> 0
B48: FLAVOR-l2. c8 r16. 500 | C48: 8 | D48: 16 | E48: 500 | F48: =G48/720 -> 0.26372222 | G48: =C48*IAAS_vcpu_EUR+D48*IAAS_ram_EUR+E48*IAAS_nvme_EUR -> 189.88 | K48: =ROUNDUP(I48*G48,2) -> 0
B49: FLAVOR-l2. c8 r16. 1000 | C49: 8 | D49: 16 | E49: 1000 | F49: =G49/720 -> 0.329 | G49: =C49*IAAS_vcpu_EUR+D49*IAAS_ram_EUR+E49*IAAS_nvme_EUR -> 236.88 | K49: =ROUNDUP(I49*G49,2) -> 0
B50: FLAVOR-l2. c16 r32. 100 | C50: 16 | D50: 32 | E50: 100 | F50: =G50/720 -> 0.40994444 | G50: =C50*IAAS_vcpu_EUR+D50*IAAS_ram_EUR+E50*IAAS_nvme_EUR -> 295.16 | K50: =ROUNDUP(I50*G50,2) -> 0
B51: FLAVOR-l2. c16 r32. 500 | C51: 16 | D51: 32 | E51: 500 | F51: =G51/720 -> 0.46216667 | G51: =C51*IAAS_vcpu_EUR+D51*IAAS_ram_EUR+E51*IAAS_nvme_EUR -> 332.76 | K51: =ROUNDUP(I51*G51,2) -> 0
B52: FLAVOR-l2. c16 r32. 1000 | C52: 16 | D52: 32 | E52: 1000 | F52: =G52/720 -> 0.52744444 | G52: =C52*IAAS_vcpu_EUR+D52*IAAS_ram_EUR+E52*IAAS_nvme_EUR -> 379.76 | K52: =ROUNDUP(I52*G52,2) -> 0
... B54: FLAVOR-l2. c32 r64. 1000 | C54: 32 | D54: 64 | E54: 1000 | F54: =G54/720 -> 0.92433333 | G54: =C54*IAAS_vcpu_EUR+D54*IAAS_ram_EUR+E54*IAAS_nvme_EUR -> 665.52 | K54: =ROUNDUP(I54*G54,2) -> 0
B55: Total | C55: {=SUM(C41:C54*I41:I54)} -> 0 | D55: {=SUM(D41:D54*I41:I54)&" GB"} -> 0 GB | E55: {=SUM(E41:E54*I41:I54)&" GB"} -> 0 GB | I55: =SUM(I41:I54) -> 0 | K55: =SUM(K41:K54) -> 0
B59: Flavors without local storage
B60: Central block storage can be purchased for the instances. See "Central block storage" in the price list.
B61: Product ID | C61: vCPU | D61: RAM (GB) | E61: Local disk (GB) | F61: Hourly | G61: 30 days | I61: Amount | K61: Infrastructure
B62: FLAVOR-b2. c1 r2 | C62: 1 | D62: 2 | E62: 0 | F62: =G62/720 -> 0.024805556 | G62: =C62*IAAS_vcpu_EUR+D62*IAAS_ram_EUR+E62*IAAS_ssd_EUR -> 17.86 | K62: =ROUNDUP(I62*G62,2) -> 0
B63: FLAVOR-b2. c1 r4 | C63: 1 | D63: 4 | E63: 0 | F63: =G63/720 -> 0.039166667 | G63: =C63*IAAS_vcpu_EUR+D63*IAAS_ram_EUR+E63*IAAS_ssd_EUR -> 28.2 | K63: =ROUNDUP(I63*G63,2) -> 0
B64: FLAVOR-b2. c2 r4 | C64: 2 | D64: 4 | E64: 0 | F64: =G64/720 -> 0.049611111 | G64: =C64*IAAS_vcpu_EUR+D64*IAAS_ram_EUR+E64*IAAS_ssd_EUR -> 35.72 | K64: =ROUNDUP(I64*G64,2) -> 0
...

Sheet SEK - Safesprings tjänster 2025
B5: Priskalkylator 2026-05-25
B8: Kontakta Safespring | D8: Valuta
B9: Telefon: 08-55 10 73 56
B10: hello@safespring.com
B15: Safespring Kubernetes Engine
B18: Alla priser är angivna i SEK, exklusive moms.
B19: Instruktioner: Fyll i önskad kvantitet i de färgade fälten.
B22: Kontrollplan
B23: Första kontrollplanet är managerat men sedan går det att addera omanagerade kontrollplan.
B24: Produkt ID | G24: Per timme | H24: Per 30 dagar | I24: Antal instanser | K24: Totalt
B25: Managed Control plane | G25: =H25/720 -> 6.8055556 | H25: 4900 | K25: =ROUNDUP(I25*H25,2) -> 0
B26: Unmanaged Control plane | G26: =H26/720 -> 0 | H26: 0 | K26: =ROUNDUP(I26*H26,2) -> 0
B27: Totalt | I27: =SUM(I14:I26)&" st" -> 0 st | K27: =SUM(K14:K26) -> 0
B30: Safespring Compute | IaaS
B33: Infrastruktur kan köras med en Open Source-licens eller med en Windows-licens
B34: Alla priser är angivna i SEK, exklusive moms.
B35: Instruktioner: Fyll i önskad kvantitet i de färgade fälten.
B38: Flavors med lokal NVMe-disk
B39: Central blocklagring kan köpas till instanserna. Se "Central blocklagring" i prislistan.
B40: Produkt ID | C40: vCPU | D40: RAM (GB) | E40: Lokal disk (GB) | G40: Per timme | H40: Per 30 dagar | I40: Antal instanser | K40: Infrastruktur
B41: FLAVOR-l2. c2 r4. 100 | C41: 2 | D41: 4 | E41: 100 | G41: =H41/720 -> 0.66666667 | H41: =C41*IAAS_vcpu_SEK+D41*IAAS_ram_SEK+E41*IAAS_nvme_SEK -> 480 | K41: =ROUNDUP(I41*H41,2) -> 0
B42: FLAVOR-l2. c2 r4. 500 | C42: 2 | D42: 4 | E42: 500 | G42: =H42/720 -> 1.2222222 | H42: =C42*IAAS_vcpu_SEK+D42*IAAS_ram_SEK+E42*IAAS_nvme_SEK -> 880 | K42: =ROUNDUP(I42*H42,2) -> 0
B43: FLAVOR-l2. c2 r4. 1000 | C43: 2 | D43: 4 | E43: 1000 | G43: =H43/720 -> 1.9166667 | H43: =C43*IAAS_vcpu_SEK+D43*IAAS_ram_SEK+E43*IAAS_nvme_SEK -> 1380 | K43: =ROUNDUP(I43*H43,2) -> 0
B44: FLAVOR-l2. c4 r8. 100 | C44: 4 | D44: 8 | E44: 100 | G44: =H44/720 -> 1.1944444 | H44: =C44*IAAS_vcpu_SEK+D44*IAAS_ram_SEK+E44*IAAS_nvme_SEK -> 860 | K44: =ROUNDUP(I44*H44,2) -> 0
B45: FLAVOR-l2. c4 r8. 500 | C45: 4 | D45: 8 | E45: 500 | G45: =H45/720 -> 1.75 | H45: =C45*IAAS_vcpu_SEK+D45*IAAS_ram_SEK+E45*IAAS_nvme_SEK -> 1260 | K45: =ROUNDUP(I45*H45,2) -> 0
B46: FLAVOR-l2. c4 r8. 1000 | C46: 4 | D46: 8 | E46: 1000 | G46: =H46/720 -> 2.4444444 | H46: =C46*IAAS_vcpu_SEK+D46*IAAS_ram_SEK+E46*IAAS_nvme_SEK -> 1760 | K46: =ROUNDUP(I46*H46,2) -> 0
B47: FLAVOR-l2. c8 r16. 100 | C47: 8 | D47: 16 | E47: 100 | G47: =H47/720 -> 2.25 | H47: =C47*IAAS_vcpu_SEK+D47*IAAS_ram_SEK+E47*IAAS_nvme_SEK -> 1620 | K47: =ROUNDUP(I47*H47,2) -> 0
B48: FLAVOR-l2. c8 r16. 500 | C48: 8 | D48: 16 | E48: 500 | G48: =H48/720 -> 2.8055556 | H48: =C48*IAAS_vcpu_SEK+D48*IAAS_ram_SEK+E48*IAAS_nvme_SEK -> 2020 | K48: =ROUNDUP(I48*H48,2) -> 0
B49: FLAVOR-l2. c8 r16. 1000 | C49: 8 | D49: 16 | E49: 1000 | G49: =H49/720 -> 3.5 | H49: =C49*IAAS_vcpu_SEK+D49*IAAS_ram_SEK+E49*IAAS_nvme_SEK -> 2520 | K49: =ROUNDUP(I49*H49,2) -> 0
B50: FLAVOR-l2. c16 r32. 100 | C50: 16 | D50: 32 | E50: 100 | G50: =H50/720 -> 4.3611111 | H50: =C50*IAAS_vcpu_SEK+D50*IAAS_ram_SEK+E50*IAAS_nvme_SEK -> 3140 | K50: =ROUNDUP(I50*H50,2) -> 0
B51: FLAVOR-l2. c16 r32. 500 | C51: 16 | D51: 32 | E51: 500 | G51: =H51/720 -> 4.9166667 | H51: =C51*IAAS_vcpu_SEK+D51*IAAS_ram_SEK+E51*IAAS_nvme_SEK -> 3540 | K51: =ROUNDUP(I51*H51,2) -> 0
B52: FLAVOR-l2. c16 r32. 1000 | C52: 16 | D52: 32 | E52: 1000 | G52: =H52/720 -> 5.6111111 | H52: =C52*IAAS_vcpu_SEK+D52*IAAS_ram_SEK+E52*IAAS_nvme_SEK -> 4040 | K52: =ROUNDUP(I52*H52,2) -> 0
... B54: FLAVOR-l2. c32 r64. 1000 | C54: 32 | D54: 64 | E54: 1000 | G54: =H54/720 -> 9.8333333 | H54: =C54*IAAS_vcpu_SEK+D54*IAAS_ram_SEK+E54*IAAS_nvme_SEK -> 7080 | K54: =ROUNDUP(I54*H54,2) -> 0
B55: Totalt | C55: {=SUM(C41:C54*I41:I54)&" st"} -> 0 st | D55: {=SUM(D41:D54*I41:I54)&" GB"} -> 0 GB | E55: {=SUM(E41:E54*I41:I54)&" GB"} -> 0 GB | I55: =SUM(I41:I54)&" st" -> 0 st | K55: =SUM(K41:K54) -> 0
B59: Flavors utan lokal disk
B60: Central blocklagring kan köpas till instanserna. Se "Central blocklagring" i prislistan.
B61: Produkt ID | C61: vCPU | D61: RAM (GB) | E61: Lokal disk (GB) | G61: Per timme | H61: Per 30 dagar | I61: Antal instanser | K61: Infrastruktur
B62: FLAVOR-b2. c1 r2 | C62: 1 | D62: 2 | E62: 0 | G62: =H62/720 -> 0.26388889 | H62: =C62*IAAS_vcpu_SEK+D62*IAAS_ram_SEK+E62*IAAS_ssd_SEK -> 190 | K62: =ROUNDUP(I62*H62,2) -> 0
B63: FLAVOR-b2. c1 r4 | C63: 1 | D63: 4 | E63: 0 | G63: =H63/720 -> 0.41666667 | H63: =C63*IAAS_vcpu_SEK+D63*IAAS_ram_SEK+E63*IAAS_ssd_SEK -> 300 | K63: =ROUNDUP(I63*H63,2) -> 0
B64: FLAVOR-b2. c2 r4 | C64: 2 | D64: 4 | E64: 0 | G64: =H64/720 -> 0.52777778 | H64: =C64*IAAS_vcpu_SEK+D64*IAAS_ram_SEK+E64*IAAS_ssd_SEK -> 380 | K64: =ROUNDUP(I64*H64,2) -> 0
...

Sheet NOK - Safespring tjenester 2025
B5: Priskalkulator 2026-05-25
B8: Kontakt Safespring | D8: Valuta
B9: Telefon: +47 35 68 88 70
B10: hello@safespring.com
B15: Safespring Kubernetes Engine
B18: Alle priser er oppgitt i NOK, eks mva.
B19: Instruksjoner: Angi ønsket antall i de fargede feltene.
B22: Kontrollplan
B23: Det første kontrollplanet er administrert, men deretter er det mulig å legge til uadministrerte kontrollplan.
B24: Produkt ID | G24: Per time | H24: Per 30 dager | I24: Antall | K24: Infrastruktur
B25: Managed Control plane | G25: =H25/720 -> 6.8055556 | H25: 4900 | K25: =ROUNDUP(I25*H25,2) -> 0
B26: Unmanaged Control plane | G26: =H26/720 -> 0 | H26: 0 | K26: =ROUNDUP(I26*H26,2) -> 0
B27: Totalt | I27: =SUM(I14:I26)&" stk." -> 0 stk. | K27: =SUM(K14:K26) -> 0
B30: Safespring Compute | IaaS
B33: Infrastruktur kan kjøres med en Open Source-lisens eller med en Windows-lisens.
B34: Alle priser er oppgitt i NOK, eks mva.
B35: Instruksjoner: Angi ønsket antall i de fargede feltene.
B38: Flavors med lokal NVMe-disk
B39: Sentral blokklagring kan kjøpes til instansene. Se "Sentral blokklagring" i prislisten.
B40: Produkt ID | C40: vCPU | D40: RAM (GB) | E40: Lokal disk (GB) | G40: Per time | H40: Per 30 dager | I40: Antall | K40: Infrastruktur
B41: FLAVOR-l2. c2 r4. 100 | C41: 2 | D41: 4 | E41: 100 | G41: =H41/720 -> 0.66666667 | H41: =C41*IAAS_vcpu_SEK+D41*IAAS_ram_SEK+E41*IAAS_nvme_SEK -> 480 | K41: =ROUNDUP(I41*H41,2) -> 0
B42: FLAVOR-l2. c2 r4. 500 | C42: 2 | D42: 4 | E42: 500 | G42: =H42/720 -> 1.2222222 | H42: =C42*IAAS_vcpu_SEK+D42*IAAS_ram_SEK+E42*IAAS_nvme_SEK -> 880 | K42: =ROUNDUP(I42*H42,2) -> 0
B43: FLAVOR-l2. c2 r4. 1000 | C43: 2 | D43: 4 | E43: 1000 | G43: =H43/720 -> 1.9166667 | H43: =C43*IAAS_vcpu_SEK+D43*IAAS_ram_SEK+E43*IAAS_nvme_SEK -> 1380 | K43: =ROUNDUP(I43*H43,2) -> 0
B44: FLAVOR-l2. c4 r8. 100 | C44: 4 | D44: 8 | E44: 100 | G44: =H44/720 -> 1.1944444 | H44: =C44*IAAS_vcpu_SEK+D44*IAAS_ram_SEK+E44*IAAS_nvme_SEK -> 860 | K44: =ROUNDUP(I44*H44,2) -> 0
B45: FLAVOR-l2. c4 r8. 500 | C45: 4 | D45: 8 | E45: 500 | G45: =H45/720 -> 1.75 | H45: =C45*IAAS_vcpu_SEK+D45*IAAS_ram_SEK+E45*IAAS_nvme_SEK -> 1260 | K45: =ROUNDUP(I45*H45,2) -> 0
B46: FLAVOR-l2. c4 r8. 1000 | C46: 4 | D46: 8 | E46: 1000 | G46: =H46/720 -> 2.4444444 | H46: =C46*IAAS_vcpu_SEK+D46*IAAS_ram_SEK+E46*IAAS_nvme_SEK -> 1760 | K46: =ROUNDUP(I46*H46,2) -> 0
B47: FLAVOR-l2. c8 r16. 100 | C47: 8 | D47: 16 | E47: 100 | G47: =H47/720 -> 2.25 | H47: =C47*IAAS_vcpu_SEK+D47*IAAS_ram_SEK+E47*IAAS_nvme_SEK -> 1620 | K47: =ROUNDUP(I47*H47,2) -> 0
B48: FLAVOR-l2. c8 r16. 500 | C48: 8 | D48: 16 | E48: 500 | G48: =H48/720 -> 2.8055556 | H48: =C48*IAAS_vcpu_SEK+D48*IAAS_ram_SEK+E48*IAAS_nvme_SEK -> 2020 | K48: =ROUNDUP(I48*H48,2) -> 0
B49: FLAVOR-l2. c8 r16. 1000 | C49: 8 | D49: 16 | E49: 1000 | G49: =H49/720 -> 3.5 | H49: =C49*IAAS_vcpu_SEK+D49*IAAS_ram_SEK+E49*IAAS_nvme_SEK -> 2520 | K49: =ROUNDUP(I49*H49,2) -> 0
B50: FLAVOR-l2. c16 r32. 100 | C50: 16 | D50: 32 | E50: 100 | G50: =H50/720 -> 4.3611111 | H50: =C50*IAAS_vcpu_SEK+D50*IAAS_ram_SEK+E50*IAAS_nvme_SEK -> 3140 | K50: =ROUNDUP(I50*H50,2) -> 0
B51: FLAVOR-l2. c16 r32. 500 | C51: 16 | D51: 32 | E51: 500 | G51: =H51/720 -> 4.9166667 | H51: =C51*IAAS_vcpu_SEK+D51*IAAS_ram_SEK+E51*IAAS_nvme_SEK -> 3540 | K51: =ROUNDUP(I51*H51,2) -> 0
B52: FLAVOR-l2. c16 r32. 1000 | C52: 16 | D52: 32 | E52: 1000 | G52: =H52/720 -> 5.6111111 | H52: =C52*IAAS_vcpu_SEK+D52*IAAS_ram_SEK+E52*IAAS_nvme_SEK -> 4040 | K52: =ROUNDUP(I52*H52,2) -> 0
... B54: FLAVOR-l2. c32 r64. 1000 | C54: 32 | D54: 64 | E54: 1000 | G54: =H54/720 -> 9.8333333 | H54: =C54*IAAS_vcpu_SEK+D54*IAAS_ram_SEK+E54*IAAS_nvme_SEK -> 7080 | K54: =ROUNDUP(I54*H54,2) -> 0
B55: Totalt | C55: =SUMPRODUCT(C41:C54,I41:I54)&" stk." -> 0 stk. | D55: {=SUM(D41:D54*I41:I54)&" GB"} -> 0 GB | E55: {=SUM(E41:E54*I41:I54)&" GB"} -> 0 GB | I55: =SUM(I41:I54)&" stk." -> 0 stk. | K55: =SUM(K41:K54) -> 0
B59: Flavors uten lokal disk
B60: Sentral blokklagring kan kjøpes til instansene. Se "Sentral blokklagring" i prislisten.
B61: Produkt ID | C61: vCPU | D61: RAM (GB) | E61: Lokal disk (GB) | G61: Per time | H61: Per 30 dager | I61: Antall | K61: Infrastruktur
B62: FLAVOR-b2. c1 r2 | C62: 1 | D62: 2 | E62: 0 | G62: ='SEK - Safesprings tjänster 2025'!G62 -> 0.26388889 | H62: =C62*IAAS_vcpu_SEK+D62*IAAS_ram_SEK+E62*IAAS_nvme_SEK -> 190 | K62: =ROUNDUP(I62*H62,2) -> 0
B63: FLAVOR-b2. c1 r4 | C63: 1 | D63: 4 | E63: 0 | G63: ='SEK - Safesprings tjänster 2025'!G63 -> 0.41666667 | H63: =C63*IAAS_vcpu_SEK+D63*IAAS_ram_SEK+E63*IAAS_nvme_SEK -> 300 | K63: =ROUNDUP(I63*H63,2) -> 0
B64: FLAVOR-b2. c2 r4 | C64: 2 | D64: 4 | E64: 0 | G64: ='SEK - Safesprings tjänster 2025'!G64 -> 0.52777778 | H64: =C64*IAAS_vcpu_SEK+D64*IAAS_ram_SEK+E64*IAAS_nvme_SEK -> 380 | K64: =ROUNDUP(I64*H64,2) -> 0
...

Sheet EUR - Safespring services 2021
B5: Price calculator 2022-01-04
B8: Contact Safespring | D8: Currency
B9: Phone: +46 855 10 73 56
B10: sales@safespring.com
D11: ="1 SEK = "&EUR&" EUR" -> 1 SEK = 0,094 EUR
B15: Safespring Compute
B18: Infrastructure as a service can run on a open source license or with a Windows license.
B19: All prices are in EUR, excluding VAT.
B20: Instructions: Enter the desired amount in the colored fields
B23: Instances with central block storage
B24: Product ID | C24: vCPU | D24: RAM (GB) | E24: Storage (GB) | G24: Hourly | H24: Monthly (30 days) | I24: Instances | K24: Infrastructure
B25: INSTANCE-b.tiny | C25: 1 | D25: 1 | E25: 40 | G25: =H25/720 -> 0.036425 | H25: =C25*IAAS_vcpu_EUR+D25*IAAS_ram_EUR+E25*IAAS_ssd_EUR -> 26.226 | J25: Instances | K25: =ROUNDUP(I25*H25,2) -> 0
B26: INSTANCE-b.small | C26: 1 | D26: 2 | E26: 40 | G26: =H26/720 -> 0.043605556 | H26: =C26*IAAS_vcpu_EUR+D26*IAAS_ram_EUR+E26*IAAS_ssd_EUR -> 31.396 | J26: =J25 -> Instances | K26: =ROUNDUP(I26*H26,2) -> 0
B27: INSTANCE-b.medium | C27: 2 | D27: 4 | E27: 40 | G27: =H27/720 -> 0.068411111 | H27: =C27*IAAS_vcpu_EUR+D27*IAAS_ram_EUR+E27*IAAS_ssd_EUR -> 49.256 | J27: =J26 -> Instances | K27: =ROUNDUP(I27*H27,2) -> 0
B28: INSTANCE-b.large | C28: 4 | D28: 8 | E28: 40 | G28: =H28/720 -> 0.11802222 | H28: =C28*IAAS_vcpu_EUR+D28*IAAS_ram_EUR+E28*IAAS_ssd_EUR -> 84.976 | J28: =J27 -> Instances | K28: =ROUNDUP(I28*H28,2) -> 0
B29: INSTANCE-b.xlarge | C29: 8 | D29: 16 | E29: 40 | G29: =H29/720 -> 0.21724444 | H29: =C29*IAAS_vcpu_EUR+D29*IAAS_ram_EUR+E29*IAAS_ssd_EUR -> 156.416 | J29: =J28 -> Instances | K29: =ROUNDUP(I29*H29,2) -> 0
B30: INSTANCE-b.2xlarge | C30: 16 | D30: 32 | E30: 40 | G30: =H30/720 -> 0.41568889 | H30: =C30*IAAS_vcpu_EUR+D30*IAAS_ram_EUR+E30*IAAS_ssd_EUR -> 299.296 | J30: =J29 -> Instances | K30: =ROUNDUP(I30*H30,2) -> 0
B31: INSTANCE-m.small | C31: 1 | D31: 4 | E31: 40 | G31: =H31/720 -> 0.057966667 | H31: =C31*IAAS_vcpu_EUR+D31*IAAS_ram_EUR+E31*IAAS_ssd_EUR -> 41.736 | J31: =J30 -> Instances | K31: =ROUNDUP(I31*H31,2) -> 0
B32: INSTANCE-m.medium | C32: 2 | D32: 8 | E32: 40 | G32: =H32/720 -> 0.097133333 | H32: =C32*IAAS_vcpu_EUR+D32*IAAS_ram_EUR+E32*IAAS_ssd_EUR -> 69.936 | J32: =J31 -> Instances | K32: =ROUNDUP(I32*H32,2) -> 0
B33: INSTANCE-m.large | C33: 4 | D33: 16 | E33: 40 | G33: =H33/720 -> 0.17546667 | H33: =C33*IAAS_vcpu_EUR+D33*IAAS_ram_EUR+E33*IAAS_ssd_EUR -> 126.336 | J33: =J32 -> Instances | K33: =ROUNDUP(I33*H33,2) -> 0
B34: INSTANCE-m.xlarge | C34: 8 | D34: 32 | E34: 40 | G34: =H34/720 -> 0.33213333 | H34: =C34*IAAS_vcpu_EUR+D34*IAAS_ram_EUR+E34*IAAS_ssd_EUR -> 239.136 | J34: =J33 -> Instances | K34: =ROUNDUP(I34*H34,2) -> 0
B35: INSTANCE-m.2xlarge | C35: 16 | D35: 64 | E35: 40 | G35: =H35/720 -> 0.64546667 | H35: =C35*IAAS_vcpu_EUR+D35*IAAS_ram_EUR+E35*IAAS_ssd_EUR -> 464.736 | J35: =J34 -> Instances | K35: =ROUNDUP(I35*H35,2) -> 0
B36: INSTANCE-m.4xlarge | C36: 32 | D36: 128 | E36: 40 | G36: =H36/720 -> 1.2721333 | H36: =C36*IAAS_vcpu_EUR+D36*IAAS_ram_EUR+E36*IAAS_ssd_EUR -> 915.936 | J36: =J35 -> Instances | K36: =ROUNDUP(I36*H36,2) -> 0
B37: INSTANCE-m.8xlarge | C37: 64 | D37: 256 | E37: 40 | G37: =H37/720 -> 2.5254667 | H37: =C37*IAAS_vcpu_EUR+D37*IAAS_ram_EUR+E37*IAAS_ssd_EUR -> 1818.336 | J37: =J36 -> Instances | K37: =ROUNDUP(I37*H37,2) -> 0
B38: Total | C38: {=SUM(C25:C37*I25:I37)} -> 0 | D38: {=SUM(D25:D37*I25:I37)} -> 0 | E38: {=SUM(E25:E37*I25:I37)} -> 0 | I38: =SUM(I25:I37) -> 0 | K38: =SUM(K25:K37)&" €" -> 0 €
B41: Instances with local storage (NVMe)
B42: Product ID | C42: vCPU | D42: RAM (GB) | E42: NVME (GB) | G42: Hourly | H42: Monthly (30 days) | I42: Instances | K42: Infrastructure
B43: INSTANCE-lb.tiny | C43: 1 | D43: 1 | E43: 10 | G43: =H43/720 -> 0.018930556 | H43: =C43*IAAS_vcpu_EUR+D43*IAAS_ram_EUR+E43*IAAS_nvme_EUR -> 13.63 | J43: =J37 -> Instances | K43: =ROUNDUP(I43*H43,2) -> 0
B44: INSTANCE-lb.small | C44: 1 | D44: 2 | E44: 20 | G44: =H44/720 -> 0.027416667 | H44: =C44*IAAS_vcpu_EUR+D44*IAAS_ram_EUR+E44*IAAS_nvme_EUR -> 19.74 | J44: =J43 -> Instances | K44: =ROUNDUP(I44*H44,2) -> 0
B45: INSTANCE-lb.medium.1d | C45: 2 | D45: 4 | E45: 250 | G45: =H45/720 -> 0.08225 | H45: =C45*IAAS_vcpu_EUR+D45*IAAS_ram_EUR+E45*IAAS_nvme_EUR -> 59.22 | J45: =J44 -> Instances | K45: =ROUNDUP(I45*H45,2) -> 0
B46: INSTANCE-lb.large.1d | C46: 4 | D46: 8 | E46: 250 | G46: =H46/720 -> 0.13186111 | H46: =C46*IAAS_vcpu_EUR+D46*IAAS_ram_EUR+E46*IAAS_nvme_EUR -> 94.94 | J46: =J45 -> Instances | K46: =ROUNDUP(I46*H46,2) -> 0
B47: INSTANCE-lb.xlarge.1d | C47: 8 | D47: 16 | E47: 250 | G47: =H47/720 -> 0.23108333 | H47: =C47*IAAS_vcpu_EUR+D47*IAAS_ram_EUR+E47*IAAS_nvme_EUR -> 166.38 | J47: =J46 -> Instances | K47: =ROUNDUP(I47*H47,2) -> 0
B48: INSTANCE-lb.2xlarge.1d | C48: 16 | D48: 32 | E48: 250 | G48: =H48/720 -> 0.42952778 | H48: =C48*IAAS_vcpu_EUR+D48*IAAS_ram_EUR+E48*IAAS_nvme_EUR -> 309.26 | J48: =J47 -> Instances | K48: =ROUNDUP(I48*H48,2) -> 0
B49: INSTANCE-lb.2xlarge.2d | C49: 16 | D49: 32 | E49: 500 | G49: =H49/720 -> 0.46216667 | H49: =C49*IAAS_vcpu_EUR+D49*IAAS_ram_EUR+E49*IAAS_nvme_EUR -> 332.76 | J49: =J48 -> Instances | K49: =ROUNDUP(I49*H49,2) -> 0
B50: INSTANCE-lb.2xlarge.4d | C50: 16 | D50: 32 | E50: 1000 | G50: =H50/720 -> 0.52744444 | H50: =C50*IAAS_vcpu_EUR+D50*IAAS_ram_EUR+E50*IAAS_nvme_EUR -> 379.76 | J50: =J49 -> Instances | K50: =ROUNDUP(I50*H50,2) -> 0
B51: INSTANCE-lb.4xlarge.1d | C51: 32 | D51: 64 | E51: 250 | G51: =H51/720 -> 0.82641667 | H51: =C51*IAAS_vcpu_EUR+D51*IAAS_ram_EUR+E51*IAAS_nvme_EUR -> 595.02 | J51: =J50 -> Instances | K51: =ROUNDUP(I51*H51,2) -> 0
B52: INSTANCE-lb.4xlarge.2d | C52: 32 | D52: 64 | E52: 500 | G52: =H52/720 -> 0.85905556 | H52: =C52*IAAS_vcpu_EUR+D52*IAAS_ram_EUR+E52*IAAS_nvme_EUR -> 618.52 | J52: =J47 -> Instances | K52: =ROUNDUP(I52*H52,2) -> 0
B53: INSTANCE-lb.4xlarge.4d | C53: 32 | D53: 64 | E53: 1000 | G53: =H53/720 -> 0.92433333 | H53: =C53*IAAS_vcpu_EUR+D53*IAAS_ram_EUR+E53*IAAS_nvme_EUR -> 665.52 | J53: =J52 -> Instances | K53: =ROUNDUP(I53*H53,2) -> 0
B54: INSTANCE-lm.small | C54: 1 | D54: 4 | E54: 20 | G54: =H54/720 -> 0.041777778 | H54: =C54*IAAS_vcpu_EUR+D54*IAAS_ram_EUR+E54*IAAS_nvme_EUR -> 30.08 | J54: =J53 -> Instances | K54: =ROUNDUP(I54*H54,2) -> 0
B55: INSTANCE-lm.medium.1d | C55: 2 | D55: 8 | E55: 250 | G55: =H55/720 -> 0.11097222 | H55: =C55*IAAS_vcpu_EUR+D55*IAAS_ram_EUR+E55*IAAS_nvme_EUR -> 79.9 | J55: =J54 -> Instances | K55: =ROUNDUP(I55*H55,2) -> 0
...

Sheet NOK - Safesprings tjeneste 2021
B5: Priskalkulator 04.01.2022
B8: Kontakt Safespring | D8: Valuta
B9: Telefon: +47 35 68 88 70
B10: sales@safespring.se
D11: ="1 SEK = "&NOK&" NOK" -> 1 SEK = 1 NOK
B15: Safespring Compute
B18: Infrastruktur kan kjøres med en gratis opensource-lisens eller med en Windows-lisens.
B19: Alle priser er oppgitt i NOK, eksklusiv mva.
B20: Instruksjoner: Angi ønsket antall i de fargede feltene.
B23: Instanser med sentral blokklagring
B24: Produkt ID | C24: vCPU | D24: RAM (GB) | E24: Disk (GB) | G24: Per time | H24: Per måned | I24: Antall instanser | K24: Infrastruktur
B25: INSTANCE-b.tiny | C25: 1 | D25: 1 | E25: 40 | G25: =H25/720 -> 0.3875 | H25: =C25*IAAS_vcpu_SEK+D25*IAAS_ram_SEK+E25*IAAS_ssd_SEK -> 279 | J25: Instanser | K25: =ROUNDUP(I25*H25,2) -> 0
B26: INSTANCE-b.small | C26: 1 | D26: 2 | E26: 40 | G26: =H26/720 -> 0.46388889 | H26: =C26*IAAS_vcpu_SEK+D26*IAAS_ram_SEK+E26*IAAS_ssd_SEK -> 334 | J26: Instanser | K26: =ROUNDUP(I26*H26,2) -> 0
B27: INSTANCE-b.medium | C27: 2 | D27: 4 | E27: 40 | G27: =H27/720 -> 0.72777778 | H27: =C27*IAAS_vcpu_SEK+D27*IAAS_ram_SEK+E27*IAAS_ssd_SEK -> 524 | J27: Instanser | K27: =ROUNDUP(I27*H27,2) -> 0
B28: INSTANCE-b.large | C28: 4 | D28: 8 | E28: 40 | G28: =H28/720 -> 1.2555556 | H28: =C28*IAAS_vcpu_SEK+D28*IAAS_ram_SEK+E28*IAAS_ssd_SEK -> 904 | J28: Instanser | K28: =ROUNDUP(I28*H28,2) -> 0
B29: INSTANCE-b.xlarge | C29: 8 | D29: 16 | E29: 40 | G29: =H29/720 -> 2.3111111 | H29: =C29*IAAS_vcpu_SEK+D29*IAAS_ram_SEK+E29*IAAS_ssd_SEK -> 1664 | J29: Instanser | K29: =ROUNDUP(I29*H29,2) -> 0
B30: INSTANCE-b.2xlarge | C30: 16 | D30: 32 | E30: 40 | G30: =H30/720 -> 4.4222222 | H30: =C30*IAAS_vcpu_SEK+D30*IAAS_ram_SEK+E30*IAAS_ssd_SEK -> 3184 | J30: Instanser | K30: =ROUNDUP(I30*H30,2) -> 0
B31: INSTANCE-m.small | C31: 1 | D31: 4 | E31: 40 | G31: =H31/720 -> 0.61666667 | H31: =C31*IAAS_vcpu_SEK+D31*IAAS_ram_SEK+E31*IAAS_ssd_SEK -> 444 | J31: Instanser | K31: =ROUNDUP(I31*H31,2) -> 0
B32: INSTANCE-m.medium | C32: 2 | D32: 8 | E32: 40 | G32: =H32/720 -> 1.0333333 | H32: =C32*IAAS_vcpu_SEK+D32*IAAS_ram_SEK+E32*IAAS_ssd_SEK -> 744 | J32: Instanser | K32: =ROUNDUP(I32*H32,2) -> 0
B33: INSTANCE-m.large | C33: 4 | D33: 16 | E33: 40 | G33: =H33/720 -> 1.8666667 | H33: =C33*IAAS_vcpu_SEK+D33*IAAS_ram_SEK+E33*IAAS_ssd_SEK -> 1344 | J33: Instanser | K33: =ROUNDUP(I33*H33,2) -> 0
B34: INSTANCE-m.xlarge | C34: 8 | D34: 32 | E34: 40 | G34: =H34/720 -> 3.5333333 | H34: =C34*IAAS_vcpu_SEK+D34*IAAS_ram_SEK+E34*IAAS_ssd_SEK -> 2544 | J34: Instanser | K34: =ROUNDUP(I34*H34,2) -> 0
B35: INSTANCE-m.2xlarge | C35: 16 | D35: 64 | E35: 40 | G35: =H35/720 -> 6.8666667 | H35: =C35*IAAS_vcpu_SEK+D35*IAAS_ram_SEK+E35*IAAS_ssd_SEK -> 4944 | J35: Instanser | K35: =ROUNDUP(I35*H35,2) -> 0
B36: INSTANCE-m.4xlarge | C36: 32 | D36: 128 | E36: 40 | G36: =H36/720 -> 13.533333 | H36: =C36*IAAS_vcpu_SEK+D36*IAAS_ram_SEK+E36*IAAS_ssd_SEK -> 9744 | J36: Instanser | K36: =ROUNDUP(I36*H36,2) -> 0
B37: INSTANCE-m.8xlarge | C37: 64 | D37: 256 | E37: 40 | G37: =H37/720 -> 26.866667 | H37: =C37*IAAS_vcpu_SEK+D37*IAAS_ram_SEK+E37*IAAS_ssd_SEK -> 19344 | J37: Instanser | K37: =ROUNDUP(I37*H37,2) -> 0
B38: Totalt | C38: {=SUM(C25:C37*I25:I37)} -> 0 | D38: {=SUM(D25:D37*I25:I37)} -> 0 | E38: {=SUM(E25:E37*I25:I37)} -> 0 | I38: =SUM(I25:I37)&" st" -> 0 st | K38: =SUM(K25:K35) -> 0
B41: Instanser med lokal lagring (NVMe-disk)
B42: Produkt ID | C42: vCPU | D42: RAM (GB) | E42: Disk (GB) | G42: Per time | H42: Per måned | I42: Antall instanser | K42: Infrastruktur
B43: INSTANCE-lb.tiny | C43: 1 | D43: 1 | E43: 10 | G43: =H43/720 -> 0.20138889 | H43: =C43*IAAS_vcpu_SEK+D43*IAAS_ram_SEK+E43*IAAS_nvme_SEK -> 145 | J43: Instanser | K43: =ROUNDUP(I43*H43,2) -> 0
B44: INSTANCE-lb.small | C44: 1 | D44: 2 | E44: 20 | G44: =H44/720 -> 0.29166667 | H44: =C44*IAAS_vcpu_SEK+D44*IAAS_ram_SEK+E44*IAAS_nvme_SEK -> 210 | J44: Instanser | K44: =ROUNDUP(I44*H44,2) -> 0
B45: INSTANCE-lb.medium.1d | C45: 2 | D45: 4 | E45: 250 | G45: =H45/720 -> 0.875 | H45: =C45*IAAS_vcpu_SEK+D45*IAAS_ram_SEK+E45*IAAS_nvme_SEK -> 630 | J45: Instanser | K45: =ROUNDUP(I45*H45,2) -> 0
B46: INSTANCE-lb.large.1d | C46: 4 | D46: 8 | E46: 250 | G46: =H46/720 -> 1.4027778 | H46: =C46*IAAS_vcpu_SEK+D46*IAAS_ram_SEK+E46*IAAS_nvme_SEK -> 1010 | J46: Instanser | K46: =ROUNDUP(I46*H46,2) -> 0
B47: INSTANCE-lb.xlarge.1d | C47: 8 | D47: 16 | E47: 250 | G47: =H47/720 -> 2.4583333 | H47: =C47*IAAS_vcpu_SEK+D47*IAAS_ram_SEK+E47*IAAS_nvme_SEK -> 1770 | J47: Instanser | K47: =ROUNDUP(I47*H47,2) -> 0
B48: INSTANCE-lb.2xlarge.1d | C48: 16 | D48: 32 | E48: 250 | G48: =H48/720 -> 4.5694444 | H48: =C48*IAAS_vcpu_SEK+D48*IAAS_ram_SEK+E48*IAAS_nvme_SEK -> 3290 | J48: Instanser | K48: =ROUNDUP(I48*H48,2) -> 0
B49: INSTANCE-lb.2xlarge.2d | C49: 16 | D49: 32 | E49: 500 | G49: =H49/720 -> 4.9166667 | H49: =C49*IAAS_vcpu_SEK+D49*IAAS_ram_SEK+E49*IAAS_nvme_SEK -> 3540 | J49: Instanser | K49: =ROUNDUP(I49*H49,2) -> 0
B50: INSTANCE-lb.2xlarge.4d | C50: 16 | D50: 32 | E50: 1000 | G50: =H50/720 -> 5.6111111 | H50: =C50*IAAS_vcpu_SEK+D50*IAAS_ram_SEK+E50*IAAS_nvme_SEK -> 4040 | J50: Instanser | K50: =ROUNDUP(I50*H50,2) -> 0
B51: INSTANCE-lb.4xlarge.1d | C51: 32 | D51: 64 | E51: 250 | G51: =H51/720 -> 8.7916667 | H51: =C51*IAAS_vcpu_SEK+D51*IAAS_ram_SEK+E51*IAAS_nvme_SEK -> 6330 | J51: Instanser | K51: =ROUNDUP(I51*H51,2) -> 0
B52: INSTANCE-lb.4xlarge.2d | C52: 32 | D52: 64 | E52: 500 | G52: =H52/720 -> 9.1388889 | H52: =C52*IAAS_vcpu_SEK+D52*IAAS_ram_SEK+E52*IAAS_nvme_SEK -> 6580 | J52: Instanser | K52: =ROUNDUP(I52*H52,2) -> 0
B53: INSTANCE-lb.4xlarge.4d | C53: 32 | D53: 64 | E53: 1000 | G53: =H53/720 -> 9.8333333 | H53: =C53*IAAS_vcpu_SEK+D53*IAAS_ram_SEK+E53*IAAS_nvme_SEK -> 7080 | J53: Instanser | K53: =ROUNDUP(I53*H53,2) -> 0
B54: INSTANCE-lm.small | C54: 1 | D54: 4 | E54: 20 | G54: =H54/720 -> 0.44444444 | H54: =C54*IAAS_vcpu_SEK+D54*IAAS_ram_SEK+E54*IAAS_nvme_SEK -> 320 | J54: Instanser | K54: =ROUNDUP(I54*H54,2) -> 0
... B66: INSTANCE-lm.8xlarge.4d | C66: 64 | D66: 256 | E66: 1000 | G66: =H66/720 -> 28.055556 | H66: =C66*IAAS_vcpu_SEK+D66*IAAS_ram_SEK+E66*IAAS_nvme_SEK -> 20200 | J66: Instanser | K66: =ROUNDUP(I66*H66,2) -> 0
...

Sheet SUNET SEK - priser 2020
B5: Priskalkylator 2020-07-02
B8: Kontakta Safespring | D8: Valuta
B9: Telefon: 08-55 10 73 56 | D9: SEK
B10: sales@safespring.se
B15: Safespring Compute
B18: Infrastruktur kan köras med kostnadsfri opensource-licens eller med Windows-licens.
B19: Alla priser är angivna i SEK, exklusive moms.
B20: Instruktioner: Fyll i önskad kvantitet i de färgade fälten.
B23: Instanser med central blocklagring
B24: Produkt ID | C24: Region | D24: vCPU | E24: RAM (GB) | F24: Disk (GB) | G24: Per timme | H24: Per månad | I24: Antal instanser | J24: Windows-licenser | K24: SQL-licenser | M24: Infrastruktur | N24: Licenser
B25: INSTANCE-b.tiny | C25: STO-1 | D25: 1 | E25: 1 | F25: 40 | G25: =H25/720 -> 17.95 | H25: =D25*IAAS_vcpu_sunet_b_m+E25*IAAS_ram_sunet_b_m+F25*IAAS_ssd_SUNET -> 12924 | L25: Instanser | M25: =ROUNDUP(I25*H25,2) -> 0 | N25: =J25*D25*SW_win.ser.201X_SEK+K25*D25*SW_ms.sql.ser_SEK -> 0
B26: INSTANCE-b.small | C26: STO-1 | D26: 1 | E26: 2 | F26: 40 | G26: =H26/720 -> 20.755556 | H26: =D26*IAAS_vcpu_sunet_b_m+E26*IAAS_ram_sunet_b_m+F26*IAAS_ssd_SUNET -> 14944 | L26: Instanser | M26: =ROUNDUP(I26*H26,2) -> 0 | N26: =J26*D26*SW_win.ser.201X_SEK+K26*D26*SW_ms.sql.ser_SEK -> 0
B27: INSTANCE-b.medium | C27: STO-1 | D27: 2 | E27: 4 | F27: 40 | G27: =H27/720 -> 41.511111 | H27: =D27*IAAS_vcpu_sunet_b_m+E27*IAAS_ram_sunet_b_m+F27*IAAS_ssd_SUNET -> 29888 | L27: Instanser | M27: =ROUNDUP(I27*H27,2) -> 0 | N27: =J27*D27*SW_win.ser.201X_SEK+K27*D27*SW_ms.sql.ser_SEK -> 0
B28: INSTANCE-b.large | C28: STO-1 | D28: 4 | E28: 8 | F28: 40 | G28: =H28/720 -> 83.022222 | H28: =D28*IAAS_vcpu_sunet_b_m+E28*IAAS_ram_sunet_b_m+F28*IAAS_ssd_SUNET -> 59776 | L28: Instanser | M28: =ROUNDUP(I28*H28,2) -> 0 | N28: =J28*D28*SW_win.ser.201X_SEK+K28*D28*SW_ms.sql.ser_SEK -> 0
B29: INSTANCE-b.xlarge | C29: STO-1 | D29: 8 | E29: 16 | F29: 40 | G29: =H29/720 -> 166.04444 | H29: =D29*IAAS_vcpu_sunet_b_m+E29*IAAS_ram_sunet_b_m+F29*IAAS_ssd_SUNET -> 119552 | L29: Instanser | M29: =ROUNDUP(I29*H29,2) -> 0 | N29: =J29*D29*SW_win.ser.201X_SEK+K29*D29*SW_ms.sql.ser_SEK -> 0
B30: INSTANCE-b.2xlarge | C30: STO-1 | D30: 16 | E30: 32 | F30: 40 | G30: =H30/720 -> 332.08889 | H30: =D30*IAAS_vcpu_sunet_b_m+E30*IAAS_ram_sunet_b_m+F30*IAAS_ssd_SUNET -> 239104 | L30: Instanser | M30: =ROUNDUP(I30*H30,2) -> 0 | N30: =J30*D30*SW_win.ser.201X_SEK+K30*D30*SW_ms.sql.ser_SEK -> 0
B31: INSTANCE-m.small | C31: STO-1 | D31: 1 | E31: 4 | F31: 40 | G31: =H31/720 -> 26.366667 | H31: =D31*IAAS_vcpu_sunet_b_m+E31*IAAS_ram_sunet_b_m+F31*IAAS_ssd_SUNET -> 18984 | L31: Instanser | M31: =ROUNDUP(I31*H31,2) -> 0 | N31: =J31*D31*SW_win.ser.201X_SEK+K31*D31*SW_ms.sql.ser_SEK -> 0
B32: INSTANCE-m.medium | C32: STO-1 | D32: 2 | E32: 8 | F32: 40 | G32: =H32/720 -> 52.733333 | H32: =D32*IAAS_vcpu_sunet_b_m+E32*IAAS_ram_sunet_b_m+F32*IAAS_ssd_SUNET -> 37968 | L32: Instanser | M32: =ROUNDUP(I32*H32,2) -> 0 | N32: =J32*D32*SW_win.ser.201X_SEK+K32*D32*SW_ms.sql.ser_SEK -> 0
B33: INSTANCE-m.large | C33: STO-1 | D33: 4 | E33: 16 | F33: 40 | G33: =H33/720 -> 105.46667 | H33: =D33*IAAS_vcpu_sunet_b_m+E33*IAAS_ram_sunet_b_m+F33*IAAS_ssd_SUNET -> 75936 | L33: Instanser | M33: =ROUNDUP(I33*H33,2) -> 0 | N33: =J33*D33*SW_win.ser.201X_SEK+K33*D33*SW_ms.sql.ser_SEK -> 0
B34: INSTANCE-m.xlarge | C34: STO-1 | D34: 8 | E34: 32 | F34: 40 | G34: =H34/720 -> 210.93333 | H34: =D34*IAAS_vcpu_sunet_b_m+E34*IAAS_ram_sunet_b_m+F34*IAAS_ssd_SUNET -> 151872 | L34: Instanser | M34: =ROUNDUP(I34*H34,2) -> 0 | N34: =J34*D34*SW_win.ser.201X_SEK+K34*D34*SW_ms.sql.ser_SEK -> 0
B35: INSTANCE-m.2xlarge | C35: STO-1 | D35: 16 | E35: 65 | F35: 40 | G35: =H35/720 -> 424.67222 | H35: =D35*IAAS_vcpu_sunet_b_m+E35*IAAS_ram_sunet_b_m+F35*IAAS_ssd_SUNET -> 305764 | L35: Instanser | M35: =ROUNDUP(I35*H35,2) -> 0 | N35: =J35*D35*SW_win.ser.201X_SEK+K35*D35*SW_ms.sql.ser_SEK -> 0
B36: Totalt | I36: =SUM(I25:I35)&" st" -> 0 st | J36: =SUM(J25:J35)&" st" -> 0 st | K36: =SUM(K25:K35)&" st" -> 0 st | M36: =SUM(M25:M35) -> 0 | N36: =SUM(N25:N35) -> 0
B39: Instanser med lokal lagring (NVMe-disk)
B40: Produkt ID | C40: Region | D40: vCPU | E40: RAM (GB) | F40: Disk (GB) | G40: Per timme | H40: Per månad | I40: Antal instanser | J40: Windows-licenser | K40: SQL-licenser | M40: Infrastruktur | N40: Licenser
B41: INSTANCE-lb.tiny | C41: STO-1 | D41: 1 | E41: 1 | F41: 10 | G41: =H41/720 -> 0.20138889 | H41: =D41*IAAS_vcpu_SUNET+E41*IAAS_ram_SUNET+F41*IAAS_nvme_SUNET -> 145 | L41: Instanser | M41: =ROUNDUP(I41*H41,2) -> 0 | N41: =J41*D41*SW_win.ser.201X_SEK+K41*D41*SW_ms.sql.ser_SEK -> 0
B42: INSTANCE-lb.large.1d | C42: STO-1 | D42: 4 | E42: 8 | F42: 250 | G42: =H42/720 -> 1.4027778 | H42: =D42*IAAS_vcpu_SUNET+E42*IAAS_ram_SUNET+F42*IAAS_nvme_SUNET -> 1010 | L42: Instanser | M42: =ROUNDUP(I42*H42,2) -> 0 | N42: =J42*D42*SW_win.ser.201X_SEK+K42*D42*SW_ms.sql.ser_SEK -> 0
B43: INSTANCE-lb.xlarge.1d | C43: STO-1 | D43: 8 | E43: 16 | F43: 250 | G43: =H43/720 -> 2.4583333 | H43: =D43*IAAS_vcpu_SUNET+E43*IAAS_ram_SUNET+F43*IAAS_nvme_SUNET -> 1770 | L43: Instanser | M43: =ROUNDUP(I43*H43,2) -> 0 | N43: =J43*D43*SW_win.ser.201X_SEK+K43*D43*SW_ms.sql.ser_SEK -> 0
B44: INSTANCE-lb.2xlarge.1d | C44: STO-1 | D44: 16 | E44: 32 | F44: 250 | G44: =H44/720 -> 4.5694444 | H44: =D44*IAAS_vcpu_SUNET+E44*IAAS_ram_SUNET+F44*IAAS_nvme_SUNET -> 3290 | L44: Instanser | M44: =ROUNDUP(I44*H44,2) -> 0 | N44: =J44*D44*SW_win.ser.201X_SEK+K44*D44*SW_ms.sql.ser_SEK -> 0
B45: INSTANCE-lb.2xlarge.2d | C45: STO-1 | D45: 16 | E45: 32 | F45: 500 | G45: =H45/720 -> 4.9166667 | H45: =D45*IAAS_vcpu_SUNET+E45*IAAS_ram_SUNET+F45*IAAS_nvme_SUNET -> 3540 | L45: Instanser | M45: =ROUNDUP(I45*H45,2) -> 0 | N45: =J45*D45*SW_win.ser.201X_SEK+K45*D45*SW_ms.sql.ser_SEK -> 0
B46: INSTANCE-lb.2xlarge.4d | C46: STO-1 | D46: 16 | E46: 32 | F46: 1000 | G46: =H46/720 -> 5.6111111 | H46: =D46*IAAS_vcpu_SUNET+E46*IAAS_ram_SUNET+F46*IAAS_nvme_SUNET -> 4040 | L46: Instanser | M46: =ROUNDUP(I46*H46,2) -> 0 | N46: =J46*D46*SW_win.ser.201X_SEK+K46*D46*SW_ms.sql.ser_SEK -> 0
B47: INSTANCE-lb.4xlarge.1d | C47: STO-1 | D47: 32 | E47: 65 | F47: 250 | G47: =H47/720 -> 8.8680556 | H47: =D47*IAAS_vcpu_SUNET+E47*IAAS_ram_SUNET+F47*IAAS_nvme_SUNET -> 6385 | L47: Instanser | M47: =ROUNDUP(I47*H47,2) -> 0 | N47: =J47*D47*SW_win.ser.201X_SEK+K47*D47*SW_ms.sql.ser_SEK -> 0
B48: INSTANCE-lb.4xlarge.2d | C48: STO-1 | D48: 32 | E48: 65 | F48: 500 | G48: =H48/720 -> 9.2152778 | H48: =D48*IAAS_vcpu_SUNET+E48*IAAS_ram_SUNET+F48*IAAS_nvme_SUNET -> 6635 | L48: Instanser | M48: =ROUNDUP(I48*H48,2) -> 0 | N48: =J48*D48*SW_win.ser.201X_SEK+K48*D48*SW_ms.sql.ser_SEK -> 0
B49: INSTANCE-lb.4xlarge.4d | C49: STO-1 | D49: 32 | E49: 65 | F49: 1000 | G49: =H49/720 -> 9.9097222 | H49: =D49*IAAS_vcpu_SUNET+E49*IAAS_ram_SUNET+F49*IAAS_nvme_SUNET -> 7135 | L49: Instanser | M49: =ROUNDUP(I49*H49,2) -> 0 | N49: =J49*D49*SW_win.ser.201X_SEK+K49*D49*SW_ms.sql.ser_SEK -> 0
B50: INSTANCE-lm.large.1d | C50: STO-1 | D50: 4 | E50: 16 | F50: 250 | G50: =H50/720 -> 2.0138889 | H50: =D50*IAAS_vcpu_SUNET+E50*IAAS_ram_SUNET+F50*IAAS_nvme_SUNET -> 1450 | L50: Instanser | M50: =ROUNDUP(I50*H50,2) -> 0 | N50: =J50*D50*SW_win.ser.201X_SEK+K50*D50*SW_ms.sql.ser_SEK -> 0
B51: INSTANCE-lm.xlarge.1d | C51: STO-1 | D51: 8 | E51: 32 | F51: 250 | G51: =H51/720 -> 3.6805556 | H51: =D51*IAAS_vcpu_SUNET+E51*IAAS_ram_SUNET+F51*IAAS_nvme_SUNET -> 2650 | L51: Instanser | M51: =ROUNDUP(I51*H51,2) -> 0 | N51: =J51*D51*SW_win.ser.201X_SEK+K51*D51*SW_ms.sql.ser_SEK -> 0
B52: INSTANCE-lm.xlarge.2d | C52: STO-1 | D52: 8 | E52: 32 | F52: 500 | G52: =H52/720 -> 4.0277778 | H52: =D52*IAAS_vcpu_SUNET+E52*IAAS_ram_SUNET+F52*IAAS_nvme_SUNET -> 2900 | L52: Instanser | M52: =ROUNDUP(I52*H52,2) -> 0 | N52: =J52*D52*SW_win.ser.201X_SEK+K52*D52*SW_ms.sql.ser_SEK -> 0
... B59: INSTANCE-lm.4xlarge.4d | C59: STO-1 | D59: 32 | E59: 131 | F59: 1000 | G59: =H59/720 -> 14.951389 | H59: =D59*IAAS_vcpu_SUNET+E59*IAAS_ram_SUNET+F59*IAAS_nvme_SUNET -> 10765 | L59: Instanser | M59: =ROUNDUP(I59*H59,2) -> 0 | N59: =J59*D59*SW_win.ser.201X_SEK+K59*D59*SW_ms.sql.ser_SEK -> 0
B60: Totalt | I60: =SUM(I41:I59)&" st" -> 0 st | J60: =SUM(J41:J59)&" st" -> 0 st | K60: =SUM(K41:K59)&" st" -> 0 st | M60: =SUM(M41:M59) -> 0 | N60: =SUM(N41:N59) -> 0
B63: SUNET Private Cloud
B64: Produkt ID | C64: Region | D64: CPU (p) core | E64: RAM (GB) | F64: Disk (GB) | G64: Per timme | H64: Per månad | I64: Antal instanser | J64: Windows-licenser | K64: SQL-licenser | M64: Infrastruktur | N64: Licenser
...

Sheet DKK - Safespring-tjenester 2025
B5: Prisberegner 2026-05-25
B8: Kontakt Safespring | D8: Valuta
B9: Telefon: +46 8-55 10 73 56
B10: hello@safespring.com
D11: Fakturaen vil være i DKK, hvor den gennemsnitlige valutakurs, baseret på valutakurserne fra ECB, pr. måned bruges til at beregne priserne.
B15: Safespring Kubernetes Engine
B18: Alle priser er i EUR, eksklusive moms.
B19: Vejledning: Udfyld det ønskede antal i de farvede felter.
B22: Kontrolplan
B23: Det første kontrolplan er administreret, men derefter er det muligt at tilføje ikke-administrerede kontrolplaner.
B24: Produkt ID | G24: Per time | H24: Per 30 dage | I24: Antal | K24: Infrastruktur
B25: Managed Control plane | G25: =H25/720 -> 0.63972222 | H25: ='EUR - Safespring services 2025'!H25 -> 460.6 | K25: =ROUNDUP(I25*H25,2) -> 0
B26: Unmanaged Control plane | G26: =H26/720 -> 0 | H26: 0 | K26: =ROUNDUP(I26*H26,2) -> 0
B27: I alt | I27: =SUM(I14:I26)&" stk." -> 0 stk. | K27: =SUM(K14:K26) -> 0
B30: Safespring Compute | IaaS
B33: Infrastruktur kan køre med en Open Source-licens eller med en Windows-licens.
B34: Alle priser er i EUR, eksklusive moms. Fakturaen vil være i DKK, hvor den gennemsnitlige valutakurs, baseret på valutakurserne fra ECB, pr. måned bruges til at beregne priserne.
B35: Vejledning: Udfyld det ønskede antal i de farvede felter.
B38: Flavors med lokal NVMe-disk
B39: Central bloklagring kan købes til instanserne. Se "Central bloklagring" i prislisten.
B40: Produkt ID | C40: vCPU | D40: RAM (GB) | E40: Lokal disk (GB) | G40: Per time | H40: Per 30 dage | I40: Antal | K40: Infrastruktur
B41: FLAVOR-l2. c2 r4. 100 | C41: 2 | D41: 4 | E41: 100 | G41: =H41/720 -> 0.062666667 | H41: =C41*IAAS_vcpu_EUR+D41*IAAS_ram_EUR+E41*IAAS_nvme_EUR -> 45.12 | K41: =ROUNDUP(I41*H41,2) -> 0
B42: FLAVOR-l2. c2 r4. 500 | C42: 2 | D42: 4 | E42: 500 | G42: =H42/720 -> 0.11488889 | H42: =C42*IAAS_vcpu_EUR+D42*IAAS_ram_EUR+E42*IAAS_nvme_EUR -> 82.72 | K42: =ROUNDUP(I42*H42,2) -> 0
B43: FLAVOR-l2. c2 r4. 1000 | C43: 2 | D43: 4 | E43: 1000 | G43: =H43/720 -> 0.18016667 | H43: =C43*IAAS_vcpu_EUR+D43*IAAS_ram_EUR+E43*IAAS_nvme_EUR -> 129.72 | K43: =ROUNDUP(I43*H43,2) -> 0
B44: FLAVOR-l2. c4 r8. 100 | C44: 4 | D44: 8 | E44: 100 | G44: =H44/720 -> 0.11227778 | H44: =C44*IAAS_vcpu_EUR+D44*IAAS_ram_EUR+E44*IAAS_nvme_EUR -> 80.84 | K44: =ROUNDUP(I44*H44,2) -> 0
B45: FLAVOR-l2. c4 r8. 500 | C45: 4 | D45: 8 | E45: 500 | G45: =H45/720 -> 0.1645 | H45: =C45*IAAS_vcpu_EUR+D45*IAAS_ram_EUR+E45*IAAS_nvme_EUR -> 118.44 | K45: =ROUNDUP(I45*H45,2) -> 0
B46: FLAVOR-l2. c4 r8. 1000 | C46: 4 | D46: 8 | E46: 1000 | G46: =H46/720 -> 0.22977778 | H46: =C46*IAAS_vcpu_EUR+D46*IAAS_ram_EUR+E46*IAAS_nvme_EUR -> 165.44 | K46: =ROUNDUP(I46*H46,2) -> 0
B47: FLAVOR-l2. c8 r16. 100 | C47: 8 | D47: 16 | E47: 100 | G47: =H47/720 -> 0.2115 | H47: =C47*IAAS_vcpu_EUR+D47*IAAS_ram_EUR+E47*IAAS_nvme_EUR -> 152.28 | K47: =ROUNDUP(I47*H47,2) -> 0
B48: FLAVOR-l2. c8 r16. 500 | C48: 8 | D48: 16 | E48: 500 | G48: =H48/720 -> 0.26372222 | H48: =C48*IAAS_vcpu_EUR+D48*IAAS_ram_EUR+E48*IAAS_nvme_EUR -> 189.88 | K48: =ROUNDUP(I48*H48,2) -> 0
B49: FLAVOR-l2. c8 r16. 1000 | C49: 8 | D49: 16 | E49: 1000 | G49: =H49/720 -> 0.329 | H49: =C49*IAAS_vcpu_EUR+D49*IAAS_ram_EUR+E49*IAAS_nvme_EUR -> 236.88 | K49: =ROUNDUP(I49*H49,2) -> 0
B50: FLAVOR-l2. c16 r32. 100 | C50: 16 | D50: 32 | E50: 100 | G50: =H50/720 -> 0.40994444 | H50: =C50*IAAS_vcpu_EUR+D50*IAAS_ram_EUR+E50*IAAS_nvme_EUR -> 295.16 | K50: =ROUNDUP(I50*H50,2) -> 0
B51: FLAVOR-l2. c16 r32. 500 | C51: 16 | D51: 32 | E51: 500 | G51: =H51/720 -> 0.46216667 | H51: =C51*IAAS_vcpu_EUR+D51*IAAS_ram_EUR+E51*IAAS_nvme_EUR -> 332.76 | K51: =ROUNDUP(I51*H51,2) -> 0
B52: FLAVOR-l2. c16 r32. 1000 | C52: 16 | D52: 32 | E52: 1000 | G52: =H52/720 -> 0.52744444 | H52: =C52*IAAS_vcpu_EUR+D52*IAAS_ram_EUR+E52*IAAS_nvme_EUR -> 379.76 | K52: =ROUNDUP(I52*H52,2) -> 0
... B54: FLAVOR-l2. c32 r64. 1000 | C54: 32 | D54: 64 | E54: 1000 | G54: =H54/720 -> 0.92433333 | H54: =C54*IAAS_vcpu_EUR+D54*IAAS_ram_EUR+E54*IAAS_nvme_EUR -> 665.52 | K54: =ROUNDUP(I54*H54,2) -> 0
B55: Total | C55: {=SUM(C41:C54*I41:I54)} -> 0 | D55: {=SUM(D41:D54*I41:I54)&" GB"} -> 0 GB | E55: {=SUM(E41:E54*I41:I54)&" GB"} -> 0 GB | I55: =SUM(I41:I54) -> 0 | K55: =SUM(K41:K54) -> 0
B59: Flavors uden lokal disk
B60: Central bloklagring kan købes til instanserne. Se "Central bloklagring" i prislisten.
B61: Produkt ID | C61: vCPU | D61: RAM (GB) | E61: Lokal disk (GB) | G61: Per time | H61: Per 30 dage | I61: Antal | K61: Infrastruktur
B62: FLAVOR-b2. c1 r2 | C62: 1 | D62: 2 | E62: 0 | G62: =H62/720 -> 0.024805556 | H62: =C62*IAAS_vcpu_EUR+D62*IAAS_ram_EUR+E62*IAAS_ssd_EUR -> 17.86 | K62: =ROUNDUP(I62*H62,2) -> 0
B63: FLAVOR-b2. c1 r4 | C63: 1 | D63: 4 | E63: 0 | G63: =H63/720 -> 0.039166667 | H63: =C63*IAAS_vcpu_EUR+D63*IAAS_ram_EUR+E63*IAAS_ssd_EUR -> 28.2 | K63: =ROUNDUP(I63*H63,2) -> 0
...

Sheet Data
B2: Safespring Compute | D2: Prissättning | E2: SEK/NOK | F2: EUR | G2: SUNET med påslag | I2: Currency Factor
B3: IAAS-ram | D3: 55 | E3: =D3*SEK -> 55 | F3: =D3*EUR -> 5.17 | G3: =(D3*(1+Safespring.price.increase))*(1+sunet.price.increase) -> 55 | I3: SEK | K3: 1
B4: IAAS-ssd | D4: 3.6 | E4: =D4*SEK -> 3.6 | F4: =D4*EUR -> 0.3384 | G4: =(D4*(1+Safespring.price.increase))*(1+sunet.price.increase) -> 3.6 | I4: EUR | K4: 0.094 | L4: uppdaterat 2026-02-27
B5: IAAS-vcpu | D5: 80 | E5: =D5*SEK -> 80 | F5: =D5*EUR -> 7.52 | G5: =(D5*(1+Safespring.price.increase))*(1+sunet.price.increase) -> 80 | I5: NOK | K5: 1
B6: IAAS-nvme | D6: 1 | E6: =D6*SEK -> 1 | F6: =D6*EUR -> 0.094 | G6: =(D6*(1+Safespring.price.increase))*(1+sunet.price.increase) -> 1
B7: IAAS-gpu | D7: 5500 | E7: =D7*SEK -> 5500 | F7: =D7*EUR -> 517 | G7: =(D7*(1+Safespring.price.increase))*(1+sunet.price.increase) -> 5500
B8: IAAS-pcpu (beräknad) | D8: 2.66 | E8: =D8*IAAS_vcpu_SEK*SEK -> 212.8 | F8: =D8*IAAS_vcpu_SEK*EUR -> 20.0032 | G8: =(D8*(1+Safespring.price.increase))*(1+sunet.price.increase) -> 2.66 | I8: Typ | J8: Antal | K8: Pris
B9: IAAS-GPU-A2 | D9: 2020 | E9: =D9*SEK -> 2020 | F9: =D9*EUR -> 189.88 | G9: =(D9*(1+Safespring.price.increase))*(1+sunet.price.increase) -> 2020 | I9: vCPU | K9: =J9*IAAS_vcpu_SEK -> 0
B10: IAAS-GPU-H100 | D10: 10904 | E10: =D10*SEK -> 10904 | F10: =D10*EUR -> 1024.976 | G10: =(D10*(1+Safespring.price.increase))*(1+sunet.price.increase) -> 10904 | I10: RAM | K10: =J10*IAAS_ram_SEK -> 0
E11: =D11*SEK -> 0 | F11: =D11*EUR -> 0 | G11: =(D11*(1+Safespring.price.increase))*(1+sunet.price.increase) -> 0 | I11: Totalt | K11: =SUM(K9:K10) -> 0
B13: Bare metal compute | D13: Prissättning | E13: SEK | F13: EUR | G13: SUNET
B14: INSTANCE-p1.2xlarge.16d | D14: =INSTANCE_p1.4xlarge.16d_SEK/2 -> 6840 | E14: =D14*SEK -> 6840 | F14: =D14*EUR -> 642.96
B15: INSTANCE-p1.4xlarge.16d | D15: 13680 | E15: =D15*SEK -> 13680 | F15: =D15*EUR -> 1285.92
B16: INSTANCE-p1.8xlarge.32d | D16: =INSTANCE_p1.4xlarge.16d_SEK*2 -> 27360 | E16: =D16*SEK -> 27360 | F16: =D16*EUR -> 2571.84
B18: Safespring Compute | D18: Prissättning | E18: SEK | F18: EUR | G18: SUNET
B19: VOLUME-large | D19: 1.2 | E19: =D19*SEK -> 1.2 | F19: =D19*EUR -> 0.1128 | G19: =(D19*(1+Safespring.price.increase))*(1+sunet.price.increase) -> 1.2
B20: VOLUME-fast | D20: 3.6 | E20: =D20*SEK -> 3.6 | F20: =D20*EUR -> 0.3384 | G20: =(D20*(1+Safespring.price.increase))*(1+sunet.price.increase) -> 3.6
B22: Safespring Backup | D22: Prissättning | E22: SEK | F22: EUR | G22: SUNET
B23: BAAS-on.demand | D23: 2.45 | E23: =D23*SEK -> 2.45 | F23: =D23*EUR -> 0.2303
B24: BAAS-small.fee | D24: 5500 | E24: =D24*SEK -> 5500 | F24: =D24*EUR -> 517
B25: BAAS-large.fee | D25: 9500 | E25: =D25*SEK -> 9500 | F25: =D25*EUR -> 893
B26: BAAS-small | D26: 1.75 | E26: =D26*SEK -> 1.75 | F26: =D26*EUR -> 0.1645
B27: BAAS-large | D27: 0.92 | E27: =D27*SEK -> 0.92 | F27: =D27*EUR -> 0.08648
B29: Safespring Storage | D29: Prissättning | E29: SEK | F29: EUR | G29: SUNET
B30: S3-storage.50 | D30: 500 | E30: =D30*SEK -> 500 | F30: =D30*EUR -> 47 | G30: 0.35
B31: S3-storage.100 | D31: 500 | E31: =D31*SEK -> 500 | F31: =D31*EUR -> 47 | G31: 0.19
B32: S3-storage.500 | D32: 500 | E32: =D32*SEK -> 500 | F32: =D32*EUR -> 47 | G32: 0.1
B33: S3-storage.1000 | D33: 500 | E33: =D33*SEK -> 500 | F33: =D33*EUR -> 47 | G33: 0.06
B34: S3-storage.quote | D34: Be om offert | E34: =D34 -> Be om offert | F34: Request a quote | G34: =S3_storage.quote_SEK -> Be om offert
B35: S3-archive.50 | D35: 350 | E35: =D35*SEK -> 350 | F35: =D35*EUR -> 32.9 | G35: 0.35
B36: S3-archive.100 | D36: 270 | E36: =D36*SEK -> 270 | F36: =D36*EUR -> 25.38 | G36: 0.19
B37: S3-archive.500 | D37: 200 | E37: =D37*SEK -> 200 | F37: =D37*EUR -> 18.8 | G37: 0.1
B38: S3-archive.1000 | D38: 185 | E38: =D38*SEK -> 185 | F38: =D38*EUR -> 17.39 | G38: 0.06
B39: S3-archive.quote | D39: Be om offert | E39: =D39 -> Be om offert | F39: Request a quote | G39: =S3_storage.quote_SEK -> Be om offert
B41: Nätverk | D41: Prissättning | E41: SEK | F41: EUR | G41: SUNET
B42: NET-publicv4 | D42: 25 | E42: =D42*SEK -> 25 | F42: =D42*EUR -> 2.35 | G42: N/A
B43: NET-publicv6 | D43: 0 | E43: =D43*SEK -> 0 | F43: =D43*EUR -> 0 | G43: N/A
B44: NET-ingress | D44: 0 | E44: =D44*SEK -> 0 | F44: =D44*EUR -> 0 | G44: N/A
B45: NET-egress | D45: 0 | E45: =D45*SEK -> 0 | F45: =D45*EUR -> 0 | G45: N/A
B46: NET-mgn.slb | D46: 275 | E46: =D46 -> 275 | F46: =D46*EUR -> 25.85 | G46: N/A
...
